<?xml version="1.0" ?>
<!-- =================================================================================== -->
<!-- |    This document was autogenerated by xacro from jaka_s5_robot.urdf.xacro       | -->
<!-- |    EDITING THIS FILE BY HAND IS NOT RECOMMENDED                                 | -->
<!-- =================================================================================== -->
<robot name="jaka_s5_robot">
  <!-- 直接包含 JAKA URDF 内容 -->
  <!-- This URDF was automatically created by SolidWorks to URDF Exporter! Originally created by Stephen Brawner (brawner@gmail.com) 
     Commit Version: 1.6.0-4-g7f85cfe  Build Version: 1.6.7995.38578
     For more information, please see http://wiki.ros.org/sw_urdf_exporter -->
  <material name="aluminum">
    <color rgba="0.5 0.5 0.5 1"/>
  </material>
  <material name="plastic">
    <color rgba="0.1 0.1 0.1 1"/>
  </material>
  <!-- LINK -->
  <link name="world"/>
  <link name="Link_00">
    <inertial>
      <origin rpy="0 0 0" xyz="0.0028167 -0.00019454 0.019544"/>
      <mass value="0.52663"/>
      <inertia ixx="0.0048763" ixy="-1.8056E-07" ixz="2.5196E-05" iyy="0.0068003" iyz="-1.7678E-09" izz="0.010618"/>
    </inertial>
    <visual>
      <origin rpy="0 0 0" xyz="0 0 0"/>
      <geometry>
        <mesh filename="package://jaka_description/meshes/jaka_s5_meshes/Link_00.STL"/>
      </geometry>
      <material name="">
        <color rgba="0.79216 0.81961 0.93333 1"/>
      </material>
    </visual>
    <collision>
      <origin rpy="0 0 0" xyz="0 0 0"/>
      <geometry>
        <mesh filename="package://jaka_description/meshes/jaka_s5_meshes/Link_00.STL"/>
      </geometry>
    </collision>
  </link>
  <link name="Link_01">
    <inertial>
      <origin rpy="0 0 0" xyz="-2.5186E-07 0.0033226 -0.001509"/>
      <mass value="15.135"/>
      <inertia ixx="0.044302" ixy="1.5349E-07" ixz="-6.1966E-07" iyy="0.043091" iyz="1.4326E-05" izz="0.030523"/>
    </inertial>
    <visual>
      <origin rpy="0 0 0" xyz="0 0 0"/>
      <geometry>
        <mesh filename="package://jaka_description/meshes/jaka_s5_meshes/Link_01.STL"/>
      </geometry>
      <material name="">
        <color rgba="0.84706 0.84706 0.84706 1"/>
      </material>
    </visual>
    <collision>
      <origin rpy="0 0 0" xyz="0 0 0"/>
      <geometry>
        <mesh filename="package://jaka_description/meshes/jaka_s5_meshes/Link_01.STL"/>
      </geometry>
    </collision>
  </link>
  <link name="Link_02">
    <inertial>
      <origin rpy="0 0 0" xyz="0.215 6.4325E-09 -0.14315"/>
      <mass value="45.847"/>
      <inertia ixx="0.10377" ixy="-1.3562E-06" ixz="2.544E-07" iyy="1.5964" iyz="2.1509E-08" izz="1.5689"/>
    </inertial>
    <visual>
      <origin rpy="0 0 0" xyz="0 0 0"/>
      <geometry>
        <mesh filename="package://jaka_description/meshes/jaka_s5_meshes/Link_02.STL"/>
      </geometry>
      <material name="">
        <color rgba="0.84706 0.84706 0.84706 1"/>
      </material>
    </visual>
    <collision>
      <origin rpy="0 0 0" xyz="0 0 0"/>
      <geometry>
        <mesh filename="package://jaka_description/meshes/jaka_s5_meshes/Link_02.STL"/>
      </geometry>
    </collision>
  </link>
  <link name="Link_03">
    <inertial>
      <origin rpy="0 0 0" xyz="0.19077 -1.059E-08 -0.010626"/>
      <mass value="18.05"/>
      <inertia ixx="0.022066" ixy="-3.4554E-06" ixz="-0.022609" iyy="0.41632" iyz="1.1508E-08" izz="0.41071"/>
    </inertial>
    <visual>
      <origin rpy="0 0 0" xyz="0 0 0"/>
      <geometry>
        <mesh filename="package://jaka_description/meshes/jaka_s5_meshes/Link_03.STL"/>
      </geometry>
      <material name="">
        <color rgba="0.84706 0.84706 0.84706 1"/>
      </material>
    </visual>
    <collision>
      <origin rpy="0 0 0" xyz="0 0 0"/>
      <geometry>
        <mesh filename="package://jaka_description/meshes/jaka_s5_meshes/Link_03.STL"/>
      </geometry>
    </collision>
  </link>
  <link name="Link_04">
    <inertial>
      <origin rpy="0 0 0" xyz="-2.1463E-06 -0.0059512 0.0026789"/>
      <mass value="5.5377"/>
      <inertia ixx="0.0092564" ixy="1.1341E-07" ixz="-1.2578E-08" iyy="0.0052251" iyz="-8.3499E-05" izz="0.0089683"/>
    </inertial>
    <visual>
      <origin rpy="0 0 0" xyz="0 0 0"/>
      <geometry>
        <mesh filename="package://jaka_description/meshes/jaka_s5_meshes/Link_04.STL"/>
      </geometry>
      <material name="">
        <color rgba="0.84706 0.84706 0.84706 1"/>
      </material>
    </visual>
    <collision>
      <origin rpy="0 0 0" xyz="0 0 0"/>
      <geometry>
        <mesh filename="package://jaka_description/meshes/jaka_s5_meshes/Link_04.STL"/>
      </geometry>
    </collision>
  </link>
  <link name="Link_05">
    <inertial>
      <origin rpy="0 0 0" xyz="-2.0304E-06 -0.0028889 -0.0023424"/>
      <mass value="6.3339"/>
      <inertia ixx="0.012993" ixy="-1.0764E-07" ixz="5.8559E-09" iyy="0.0058454" iyz="4.5426E-05" izz="0.0127"/>
    </inertial>
    <visual>
      <origin rpy="0 0 0" xyz="0 0 0"/>
      <geometry>
        <mesh filename="package://jaka_description/meshes/jaka_s5_meshes/Link_05.STL"/>
      </geometry>
      <material name="">
        <color rgba="0.84706 0.84706 0.84706 1"/>
      </material>
    </visual>
    <collision>
      <origin rpy="0 0 0" xyz="0 0 0"/>
      <geometry>
        <mesh filename="package://jaka_description/meshes/jaka_s5_meshes/Link_05.STL"/>
      </geometry>
    </collision>
  </link>
  <link name="Link_06">
    <inertial>
      <origin rpy="0 0 0" xyz="-0.00024331 0.00030548 -0.026411"/>
      <mass value="0.23261"/>
      <inertia ixx="0.00071853" ixy="-6.9778E-07" ixz="-6.378E-07" iyy="0.00072375" iyz="8.3072E-07" izz="0.0011337"/>
    </inertial>
    <visual>
      <origin rpy="0 0 0" xyz="0 0 0"/>
      <geometry>
        <mesh filename="package://jaka_description/meshes/jaka_s5_meshes/Link_06.STL"/>
      </geometry>
      <material name="">
        <color rgba="0.79216 0.81961 0.93333 1"/>
      </material>
    </visual>
    <collision>
      <origin rpy="0 0 0" xyz="0 0 0"/>
      <geometry>
        <mesh filename="package://jaka_description/meshes/jaka_s5_meshes/Link_06.STL"/>
      </geometry>
    </collision>
  </link>
  <!-- JOINT -->
  <joint name="fixed" type="fixed">
    <origin rpy="0 0 0" xyz="0 0 0.0001"/>
    <parent link="world"/>
    <child link="Link_00"/>
  </joint>
  <joint name="joint_1" type="revolute">
    <origin rpy="0 0 0" xyz="0 0 0.12015"/>
    <parent link="Link_00"/>
    <child link="Link_01"/>
    <axis xyz="0 0 1"/>
    <limit effort="3000" lower="-6.28" upper="6.28" velocity="3.14"/>
  </joint>
  <joint name="joint_2" type="revolute">
    <origin rpy="1.5708 0 0" xyz="0 0 0"/>
    <parent link="Link_01"/>
    <child link="Link_02"/>
    <axis xyz="0 0 1"/>
    <limit effort="5000" lower="-1.48" upper="4.62" velocity="3.14"/>
  </joint>
  <joint name="joint_3" type="revolute">
    <origin rpy="0 0 0" xyz="0.43 0 0"/>
    <parent link="Link_02"/>
    <child link="Link_03"/>
    <axis xyz="0 0 1"/>
    <limit effort="5000" lower="-3.05" upper="3.05" velocity="3.14"/>
  </joint>
  <joint name="joint_4" type="revolute">
    <origin rpy="0 0 0" xyz="0.3685 0 -0.114"/>
    <parent link="Link_03"/>
    <child link="Link_04"/>
    <axis xyz="0 0 1"/>
    <limit effort="2000" lower="-1.48" upper="4.62" velocity="3.14"/>
  </joint>
  <joint name="joint_5" type="revolute">
    <origin rpy="1.5708 0 0" xyz="0 -0.1135 0"/>
    <parent link="Link_04"/>
    <child link="Link_05"/>
    <axis xyz="0 0 1"/>
    <limit effort="3000" lower="-6.28" upper="6.28" velocity="3.14"/>
  </joint>
  <joint name="joint_6" type="revolute">
    <origin rpy="-1.5708 0 0" xyz="0.00026137 0.1175 0.00025782"/>
    <parent link="Link_05"/>
    <child link="Link_06"/>
    <axis xyz="0 0 1"/>
    <limit effort="1000" lower="-6.28" upper="6.28" velocity="3.14"/>
  </joint>
  <transmission name="trans_joint_1">
    <type>transmission_interface/SimpleTransmission</type>
    <joint name="joint_1">
      <hardwareInterface>hardware_interface/PositionJointInterface</hardwareInterface>
    </joint>
    <actuator name="joint_1_motor">
      <hardwareInterface>hardware_interface/PositionJointInterface</hardwareInterface>
      <mechanicalReduction>1</mechanicalReduction>
    </actuator>
  </transmission>
  <transmission name="trans_joint_2">
    <type>transmission_interface/SimpleTransmission</type>
    <joint name="joint_2">
      <hardwareInterface>hardware_interface/PositionJointInterface</hardwareInterface>
    </joint>
    <actuator name="joint_2_motor">
      <hardwareInterface>hardware_interface/PositionJointInterface</hardwareInterface>
      <mechanicalReduction>1</mechanicalReduction>
    </actuator>
  </transmission>
  <transmission name="trans_joint_3">
    <type>transmission_interface/SimpleTransmission</type>
    <joint name="joint_3">
      <hardwareInterface>hardware_interface/PositionJointInterface</hardwareInterface>
    </joint>
    <actuator name="joint_3_motor">
      <hardwareInterface>hardware_interface/PositionJointInterface</hardwareInterface>
      <mechanicalReduction>1</mechanicalReduction>
    </actuator>
  </transmission>
  <transmission name="trans_joint_4">
    <type>transmission_interface/SimpleTransmission</type>
    <joint name="joint_4">
      <hardwareInterface>hardware_interface/PositionJointInterface</hardwareInterface>
    </joint>
    <actuator name="joint_4_motor">
      <hardwareInterface>hardware_interface/PositionJointInterface</hardwareInterface>
      <mechanicalReduction>1</mechanicalReduction>
    </actuator>
  </transmission>
  <transmission name="trans_joint_5">
    <type>transmission_interface/SimpleTransmission</type>
    <joint name="joint_5">
      <hardwareInterface>hardware_interface/PositionJointInterface</hardwareInterface>
    </joint>
    <actuator name="joint_5_motor">
      <hardwareInterface>hardware_interface/PositionJointInterface</hardwareInterface>
      <mechanicalReduction>1</mechanicalReduction>
    </actuator>
  </transmission>
  <transmission name="trans_joint_6">
    <type>transmission_interface/SimpleTransmission</type>
    <joint name="joint_6">
      <hardwareInterface>hardware_interface/PositionJointInterface</hardwareInterface>
    </joint>
    <actuator name="joint_6_motor">
      <hardwareInterface>hardware_interface/PositionJointInterface</hardwareInterface>
      <mechanicalReduction>1</mechanicalReduction>
    </actuator>
  </transmission>
  <gazebo>
    <plugin filename="libgazebo_ros_control.so" name="gazebo_ros_control">
      <robotNamespace>/</robotNamespace>
    </plugin>
  </gazebo>
  <joint name="ag145_gripper_base_joint" type="fixed">
    <parent link="Link_06"/>
    <child link="ag145_gripper_base_link"/>
    <origin rpy="0 0 0.78539815" xyz="0 0 0.003"/>
  </joint>
  <link name="ag145_gripper_base_link">
    <visual>
      <geometry>
        <mesh filename="package://dh_robotics_ag145_description/meshes/visual/base_link.STL"/>
      </geometry>
    </visual>
    <collision>
      <geometry>
        <mesh filename="package://dh_robotics_ag145_description/meshes/visual/base_link.STL"/>
      </geometry>
    </collision>
    <inertial>
      <mass value="0.0244063265095657"/>
      <origin xyz="4.22096179276271E-09 -8.66337897962713E-05 0.00351545641909857"/>
      <inertia ixx="5.17090412144922E-06" ixy="2.1574281704417E-13" ixz="-1.62385477492139E-13" iyy="1.55299243331649E-05" iyz="-3.38892310365514E-09" izz="2.02963394517234E-05"/>
    </inertial>
  </link>
  <gazebo reference="ag145_gripper_base_link">
    <implicitSpringDamper>1</implicitSpringDamper>
    <mu1>100000</mu1>
    <mu2>100000</mu2>
    <kp>100000000.0</kp>
    <kd>1.0</kd>
  </gazebo>
  <joint name="ag145_gripper_finger1_joint" type="revolute">
    <parent link="ag145_gripper_base_link"/>
    <child link="ag145_gripper_finger1_knuckle_link"/>
    <axis xyz="0 -1 0"/>
    <origin rpy="0.0 0.0 3.141592653589793" xyz="-0.016 0 0.10586"/>
    <limit effort="1000" lower="-0.65" upper="0.0" velocity="100.0"/>
  </joint>
  <joint name="ag145_gripper_finger2_joint" type="revolute">
    <parent link="ag145_gripper_base_link"/>
    <child link="ag145_gripper_finger2_knuckle_link"/>
    <axis xyz="0 -1 0"/>
    <origin rpy="0.0 0.0 0.0" xyz="0.016  0 0.10586 "/>
    <limit effort="1000" lower="-3.14" upper="3.14" velocity="100.0"/>
    <mimic joint="ag145_gripper_finger1_joint"/>
  </joint>
  <link name="ag145_gripper_finger1_knuckle_link">
    <visual>
      <geometry>
        <mesh filename="package://dh_robotics_ag145_description/meshes/visual/crank_Link.STL"/>
      </geometry>
    </visual>
    <collision>
      <geometry>
        <mesh filename="package://dh_robotics_ag145_description/meshes/visual/crank_Link.STL"/>
      </geometry>
    </collision>
    <inertial>
      <mass value="0.0039541"/>
      <origin xyz="0.019413 1.0484E-09 -0.0013793"/>
      <inertia ixx="1.1534E-06" ixy="-3.3307E-14" ixz="5.4175E-09" iyy="6.8389E-07" iyz="7.7878E-15" izz="1.7667E-06"/>
    </inertial>
  </link>
  <gazebo reference="ag145_gripper_finger1_knuckle_link">
    <implicitSpringDamper>1</implicitSpringDamper>
    <mu1>100000</mu1>
    <mu2>100000</mu2>
    <kp>100000000.0</kp>
    <kd>1.0</kd>
  </gazebo>
  <link name="ag145_gripper_finger2_knuckle_link">
    <visual>
      <geometry>
        <mesh filename="package://dh_robotics_ag145_description/meshes/visual/crank_Link.STL"/>
      </geometry>
    </visual>
    <collision>
      <geometry>
        <mesh filename="package://dh_robotics_ag145_description/meshes/visual/crank_Link.STL"/>
      </geometry>
    </collision>
    <inertial>
      <mass value="0.0039541"/>
      <origin xyz="0.019413 0.00025 -0.0013793"/>
      <inertia ixx="1.1534E-06" ixy="-3.3307E-14" ixz="5.4175E-09" iyy="6.8389E-07" iyz="7.7878E-15" izz="1.7667E-06"/>
    </inertial>
  </link>
  <gazebo reference="ag145_gripper_finger2_knuckle_link">
    <implicitSpringDamper>1</implicitSpringDamper>
    <mu1>100000</mu1>
    <mu2>100000</mu2>
    <kp>100000000.0</kp>
    <kd>1.0</kd>
  </gazebo>
  <joint name="ag145_gripper_finger1_finger_joint" type="continuous">
    <parent link="ag145_gripper_finger1_knuckle_link"/>
    <child link="ag145_gripper_finger1_finger_link"/>
    <axis xyz="0 -1 0"/>
    <origin rpy="0 0 0" xyz="0.036999 0 -0.00019698"/>
    <limit effort="105" lower="-3.14" upper="3.14" velocity="100.0"/>
    <mimic joint="ag145_gripper_finger1_joint" multiplier="0.5" offset="0"/>
  </joint>
  <joint name="ag145_gripper_finger2_finger_joint" type="continuous">
    <parent link="ag145_gripper_finger2_knuckle_link"/>
    <child link="ag145_gripper_finger2_finger_link"/>
    <axis xyz="0 -1 0"/>
    <origin rpy="0 0 0" xyz="0.036999 0 -0.00019698"/>
    <limit effort="105" lower="-3.14" upper="3.14" velocity="100.0"/>
    <mimic joint="ag145_gripper_finger1_joint" multiplier="0.5" offset="0"/>
  </joint>
  <link name="ag145_gripper_finger1_finger_link">
    <visual>
      <geometry>
        <mesh filename="package://dh_robotics_ag145_description/meshes/visual/rod_Link.STL"/>
      </geometry>
    </visual>
    <collision>
      <geometry>
        <mesh filename="package://dh_robotics_ag145_description/meshes/visual/rod_Link.STL"/>
      </geometry>
    </collision>
    <inertial>
      <mass value="0.01141"/>
      <origin xyz="-0.012522 -9.1789E-09 0.034743"/>
      <inertia ixx="7.7273E-06" ixy="5.2238E-14" ixz="2.7021E-06" iyy="7.7164E-06" iyz="2.4255E-13" izz="2.4386E-06"/>
    </inertial>
  </link>
  <gazebo reference="ag145_gripper_finger1_finger_link">
    <implicitSpringDamper>1</implicitSpringDamper>
    <mu1>100000</mu1>
    <mu2>100000</mu2>
    <kp>100000000.0</kp>
    <kd>1.0</kd>
  </gazebo>
  <link name="ag145_gripper_finger2_finger_link">
    <visual>
      <geometry>
        <mesh filename="package://dh_robotics_ag145_description/meshes/visual/rod_Link.STL"/>
      </geometry>
    </visual>
    <collision>
      <geometry>
        <mesh filename="package://dh_robotics_ag145_description/meshes/visual/rod_Link.STL"/>
      </geometry>
    </collision>
    <inertial>
      <mass value="0.01141"/>
      <origin xyz="-0.012522 -0.00025001 0.034743"/>
      <inertia ixx="7.7273E-06" ixy="5.2238E-14" ixz="2.7021E-06" iyy="7.7164E-06" iyz="2.4255E-13" izz="2.4386E-06"/>
    </inertial>
  </link>
  <gazebo reference="ag145_gripper_finger2_finger_link">
    <implicitSpringDamper>1</implicitSpringDamper>
    <mu1>100000</mu1>
    <mu2>100000</mu2>
    <kp>100000000.0</kp>
    <kd>1.0</kd>
  </gazebo>
  <joint name="ag145_gripper_finger1_inner_knuckle_joint" type="continuous">
    <parent link="ag145_gripper_base_link"/>
    <child link="ag145_gripper_finger1_inner_knuckle_link"/>
    <axis xyz="0 -1 0"/>
    <origin rpy="0.0 0.0 3.141592653589793" xyz="-0.016 0 0.10586"/>
    <limit effort="105" lower="-3.14" upper="3.14" velocity="100.0"/>
    <mimic joint="ag145_gripper_finger1_joint" multiplier="1.49" offset="0"/>
  </joint>
  <joint name="ag145_gripper_finger2_inner_knuckle_joint" type="continuous">
    <parent link="ag145_gripper_base_link"/>
    <child link="ag145_gripper_finger2_inner_knuckle_link"/>
    <axis xyz="0 -1 0"/>
    <origin rpy="0.0 0.0 0.0" xyz="0.016 0 0.10586"/>
    <limit effort="105" lower="-3.14" upper="3.14" velocity="100.0"/>
    <mimic joint="ag145_gripper_finger1_joint" multiplier="1.49" offset="0"/>
  </joint>
  <link name="ag145_gripper_finger1_inner_knuckle_link">
    <visual>
      <geometry>
        <mesh filename="package://dh_robotics_ag145_description/meshes/visual/proximal_phalanx_Link.STL"/>
      </geometry>
    </visual>
    <collision>
      <geometry>
        <mesh filename="package://dh_robotics_ag145_description/meshes/visual/proximal_phalanx_Link.STL"/>
      </geometry>
    </collision>
    <inertial>
      <mass value="0.017156"/>
      <origin xyz="-0.0051218 -8.3333E-10 0.038185"/>
      <inertia ixx="1.5431E-05" ixy="3.7731E-14" ixz="1.2687E-06" iyy="1.2149E-05" iyz="-3.4837E-13" izz="3.7944E-06"/>
    </inertial>
  </link>
  <gazebo reference="ag145_gripper_finger1_inner_knuckle_link">
    <implicitSpringDamper>1</implicitSpringDamper>
    <mu1>100000</mu1>
    <mu2>100000</mu2>
    <kp>100000000.0</kp>
    <kd>1.0</kd>
  </gazebo>
  <link name="ag145_gripper_finger2_inner_knuckle_link">
    <visual>
      <geometry>
        <mesh filename="package://dh_robotics_ag145_description/meshes/visual/proximal_phalanx_Link.STL"/>
      </geometry>
    </visual>
    <collision>
      <geometry>
        <mesh filename="package://dh_robotics_ag145_description/meshes/visual/proximal_phalanx_Link.STL"/>
      </geometry>
    </collision>
    <inertial>
      <mass value="0.017156"/>
      <origin xyz="-0.0051218 -8.3333E-10 0.038185"/>
      <inertia ixx="1.5431E-05" ixy="3.7731E-14" ixz="1.2687E-06" iyy="1.2149E-05" iyz="-3.4837E-13" izz="3.7944E-06"/>
    </inertial>
  </link>
  <gazebo reference="ag145_gripper_finger2_inner_knuckle_link">
    <implicitSpringDamper>1</implicitSpringDamper>
    <mu1>100000</mu1>
    <mu2>100000</mu2>
    <kp>100000000.0</kp>
    <kd>1.0</kd>
  </gazebo>
  <joint name="ag145_gripper_finger1_finger_tip_joint" type="continuous">
    <parent link="ag145_gripper_finger1_inner_knuckle_link"/>
    <child link="ag145_gripper_finger1_finger_tip_link"/>
    <axis xyz="0 1 0"/>
    <origin rpy="0.0 0.0 0.0" xyz="-0.0081054 0 0.086119 "/>
    <limit effort="0.1" lower="-3.14" upper="3.14" velocity="100.0"/>
    <mimic joint="ag145_gripper_finger1_joint" multiplier="1.49"/>
  </joint>
  <joint name="ag145_gripper_finger2_finger_tip_joint" type="continuous">
    <parent link="ag145_gripper_finger2_inner_knuckle_link"/>
    <child link="ag145_gripper_finger2_finger_tip_link"/>
    <axis xyz="0 1 0"/>
    <origin rpy="0.0 0.0 0.0" xyz="-0.0081054 0 0.086119  "/>
    <limit effort="0.1" lower="-3.14" upper="3.14" velocity="100.0"/>
    <mimic joint="ag145_gripper_finger1_joint" multiplier="1.49"/>
  </joint>
  <link name="ag145_gripper_finger1_finger_tip_link">
    <visual>
      <geometry>
        <mesh filename="package://dh_robotics_ag145_description/meshes/visual/distal_phalanx_Link.STL"/>
      </geometry>
    </visual>
    <collision>
      <geometry>
        <mesh filename="package://dh_robotics_ag145_description/meshes/visual/distal_phalanx_Link.STL"/>
      </geometry>
    </collision>
    <inertial>
      <mass value="0.012397"/>
      <origin xyz="0.0019731 -1.4867E-09 0.010631"/>
      <inertia ixx="1.0948E-06" ixy="4.5713E-14" ixz="1.3947E-07" iyy="1.0269E-06" iyz="-5.5222E-15" izz="8.431E-07"/>
    </inertial>
  </link>
  <gazebo reference="ag145_gripper_finger1_finger_tip_link">
    <implicitSpringDamper>1</implicitSpringDamper>
    <mu1>100000</mu1>
    <mu2>100000</mu2>
    <kp>100000000.0</kp>
    <kd>1.0</kd>
  </gazebo>
  <link name="ag145_gripper_finger2_finger_tip_link">
    <visual>
      <geometry>
        <mesh filename="package://dh_robotics_ag145_description/meshes/visual/distal_phalanx_Link.STL"/>
      </geometry>
    </visual>
    <collision>
      <geometry>
        <mesh filename="package://dh_robotics_ag145_description/meshes/visual/distal_phalanx_Link.STL"/>
      </geometry>
    </collision>
    <inertial>
      <mass value="0.012397"/>
      <origin xyz="0.0019731 3.1569E-10 0.010631"/>
      <inertia ixx="1.0948E-06" ixy="-9.4676E-15" ixz="1.3947E-07" iyy="1.0269E-06" iyz="1.771E-14" izz="8.431E-07"/>
    </inertial>
  </link>
  <gazebo reference="ag145_gripper_finger2_finger_tip_link">
    <implicitSpringDamper>1</implicitSpringDamper>
    <mu1>100000</mu1>
    <mu2>100000</mu2>
    <kp>100000000.0</kp>
    <kd>1.0</kd>
  </gazebo>
  <transmission name="ag145_gripper_finger1_trans">
    <type>transmission_interface/SimpleTransmission</type>
    <joint name="ag145_gripper_finger1_joint">
      <hardwareInterface>PositionJointInterface</hardwareInterface>
    </joint>
    <actuator name="ag145_gripper_finger1_motor">
      <mechanicalReduction>1</mechanicalReduction>
      <hardwareInterface>PositionJointInterface</hardwareInterface>
    </actuator>
  </transmission>
  <gazebo>
    <!-- loading plugin: mimic joints works in gazebo now -->
    <plugin filename="libroboticsgroup_gazebo_mimic_joint_plugin.so" name="ag145_mimic_dh_robotics_ag145_1">
      <joint>ag145_gripper_finger1_joint</joint>
      <mimicJoint>ag145_gripper_finger2_joint</mimicJoint>
      <multiplier>1.0</multiplier>
      <offset>0.0</offset>
    </plugin>
    <plugin filename="libroboticsgroup_gazebo_mimic_joint_plugin.so" name="ag145_mimic_dh_robotics_ag145_2">
      <joint>ag145_gripper_finger1_joint</joint>
      <mimicJoint>ag145_gripper_finger2_inner_knuckle_joint</mimicJoint>
      <multiplier>1.49</multiplier>
      <offset>0.0</offset>
    </plugin>
    <plugin filename="libroboticsgroup_gazebo_mimic_joint_plugin.so" name="ag145_mimic_dh_robotics_ag145_3">
      <joint>ag145_gripper_finger1_joint</joint>
      <mimicJoint>ag145_gripper_finger1_inner_knuckle_joint</mimicJoint>
      <multiplier>1.49</multiplier>
      <offset>0.0</offset>
    </plugin>
    <plugin filename="libroboticsgroup_gazebo_mimic_joint_plugin.so" name="ag145_mimic_dh_robotics_ag145_4">
      <joint>ag145_gripper_finger1_joint</joint>
      <mimicJoint>ag145_gripper_finger1_finger_tip_joint</mimicJoint>
      <multiplier>1.49</multiplier>
      <offset>0.0</offset>
    </plugin>
    <plugin filename="libroboticsgroup_gazebo_mimic_joint_plugin.so" name="ag145_mimic_dh_robotics_ag145_5">
      <joint>ag145_gripper_finger1_joint</joint>
      <mimicJoint>ag145_gripper_finger2_finger_tip_joint</mimicJoint>
      <multiplier>1.49</multiplier>
      <offset>0.0</offset>
    </plugin>
    <plugin filename="libroboticsgroup_gazebo_mimic_joint_plugin.so" name="ag145_mimic_dh_robotics_ag145_6">
      <joint>ag145_gripper_finger1_joint</joint>
      <mimicJoint>ag145_gripper_finger1_finger_joint</mimicJoint>
      <multiplier>0.5</multiplier>
      <offset>0.0</offset>
    </plugin>
    <plugin filename="libroboticsgroup_gazebo_mimic_joint_plugin.so" name="ag145_mimic_dh_robotics_ag145_7">
      <joint>ag145_gripper_finger1_joint</joint>
      <mimicJoint>ag145_gripper_finger2_finger_joint</mimicJoint>
      <multiplier>0.5</multiplier>
      <offset>0.0</offset>
    </plugin>
  </gazebo>
  <!-- camera body, with origin at bottom screw mount -->
  <joint name="camera_joint" type="fixed">
    <origin rpy="0 -1.5707963267948966 2.356194490192345" xyz="0.0514278762 -0.0514278762 0.01358"/>
    <parent link="Link_06"/>
    <child link="camera_bottom_screw_frame"/>
  </joint>
  <link name="camera_bottom_screw_frame"/>
  <joint name="camera_link_joint" type="fixed">
    <origin rpy="0 0 0" xyz="0.010600000000000002 0.0175 0.0125"/>
    <parent link="camera_bottom_screw_frame"/>
    <child link="camera_link"/>
  </joint>
  <link name="camera_link">
    <visual>
      <!-- the mesh origin is at front plate in between the two infrared camera axes -->
      <origin rpy="1.5707963267948966 0 1.5707963267948966" xyz="0.0043 -0.0175 0"/>
      <geometry>
        <mesh filename="package://realsense2_description/meshes/d435.dae"/>
      </geometry>
    </visual>
    <collision>
      <origin rpy="0 0 0" xyz="0 -0.0175 0"/>
      <geometry>
        <box size="0.02505 0.09 0.025"/>
      </geometry>
    </collision>
    <inertial>
      <!-- The following are not reliable values, and should not be used for modeling -->
      <mass value="0.072"/>
      <origin xyz="0 0 0"/>
      <inertia ixx="0.003881243" ixy="0.0" ixz="0.0" iyy="0.000498940" iyz="0.0" izz="0.003879257"/>
    </inertial>
  </link>
</robot>
